Workbook

Sheet Instrucciones
B2: CONTROL DE INSUMOS CRÍTICOS — SIMET-USACH (ARCHIVO CONSOLIDADO)
B4: Qué reemplaza este archivo
B5: Este archivo unifica en una sola hoja los tres que se usaban por separado: Clasificación ABC Multicriterio, Ficha de Consumo por Operación, y Simulador de Alertas de Stock. Cada insumo aparece una sola vez, con todos sus datos juntos — ya no hay que mantener el Costo unitario, la Clase ABC o el Tiempo de reposición repetidos en tres archivos distintos.
B7: Cómo funciona
B8: 1. Complete las columnas amarillas de cada insumo: Costo unitario, N° de unidades por cambio de set, Frecuencia de uso mensual, Rendimiento (probetas por cambio), Impacto operacional (1-5), Tiempo de reposición (días) y Ubicación (estante/repisa/zona donde se guarda físicamente). El Stock actual ya NO se escribe a mano: se calcula solo a partir de las hojas "Registro de Ingresos" y "Registro de Egresos" (ver punto 9).
B9: 2. La Frecuencia de uso mensual es un solo dato que ahora alimenta tanto la clasificación ABC como el cálculo de stock mínimo — antes este dato estaba separado como 'Consumo promedio mensual' en el Simulador; ya no hace falta escribirlo dos veces.
B10: 3. Costo por cambio de set, Costo por probeta, Puntaje ponderado, Ranking, % acumulado, Clasificación ABC, Factor de seguridad, Stock actual, Stock mínimo, Alerta de nivel de stock, Fecha proyectada, Día proyectado y Alerta de ventana de compra se calculan solos. No los edite.
B11: 4. Los pesos de los 4 criterios de la clasificación ABC (celdas B4:B7 más abajo) deben sumar 1.
B12: 5. La Clasificación ABC solo se calcula cuando el insumo tiene Costo, Frecuencia, Impacto y Tiempo de reposición completos. Un insumo sin esos 4 datos queda sin clasificar, pero puede igual tener datos de Rendimiento/Costo por probeta o de Stock si los complementó por separado.
B13: 6. Fecha de hoy (para las alertas): se actualiza sola, pero puede sobrescribirla para simular un escenario.
B14: 7. Ventana SDT-USACH: día 1 al día 20 de cada mes (20 = último día para facturar). No editable.
B15: 8. Se incluyó una fila de ejemplo (ID 0, en gris) — no la use como dato real.
... B25: 11. La hoja "Vista General" muestra en una sola tabla, ordenable y filtrable, todos los insumos con su clase ABC, ubicación, stock actual, stock mínimo y alertas vigentes — útil para una revisión rápida sin recorrer todas las columnas de cálculo del Catálogo.

Sheet Listas
A1: Categoría | B1: Operación | C1: Fuente del dato
A2: Consumible de ensayo | B2: Corte | C2: Compra 2025-2026 (estimado por volumen)
A3: Rendimiento múltiple (herramienta) | B3: Fresado | C3: Entrevista personal técnico
A4: EPP-Seguridad | B4: Torneado | C4: Observación directa
A5: Insumo general | B5: Lijado | C5: Estimación / por confirmar
B6: Ensayo
B7: Desbaste
B8: Pulido
B9: Ataque químico

Sheet Catálogo de Insumos
A1: CATÁLOGO CONSOLIDADO DE INSUMOS CRÍTICOS — SIMET-USACH
A3: Pesos de los criterios ABC (deben sumar 1) | D3: Fecha de hoy (para alertas): | E3: =TODAY() -> 46265
A4: Peso — Costo unitario | B4: 0.0411 | D4: Ventana SDT-USACH: | E4: Día 1 al 20 (20 = último día para facturar)
A5: Peso — Frecuencia de uso | B5: 0.3129
A6: Peso — Impacto operacional | B6: 0.5691
A7: Peso — Tiempo de reposición | B7: 0.0769
A8: Suma de pesos (debe ser 1.00) | B8: =SUM(B4:B7) -> 1
N9: Ranking | O9: % acumulado | P9: Clase ABC | Q9: Factor de seguridad | R9: Stock actual | S9: Stock mínimo
A10: ID | B10: Insumo | C10: Categoría | D10: Operación | E10: Costo unitario (CLP) | F10: N° unidades por cambio | G10: Costo por cambio de set (CLP) | H10: Frecuencia de uso mensual | I10: Rendimiento (probetas/cambio) | J10: Costo por probeta (CLP) | K10: Impacto operacional (1-5) | L10: Tiempo de reposición (días) | M10: Puntaje ponderado | N10: =MIN(E11:E79) -> 14 | O10: =MAX(E11:E79) -> 142800 | P10: =MIN(H11:H79) -> 0.08 | Q10: =MAX(H11:H79) -> 20 | R10: =MIN(L11:L79) -> 1 | S10: =MAX(L11:L79) -> 10 | T10: Alerta nivel de stock | U10: Fecha proyectada stock mínimo | V10: Día del mes proyectado | W10: Alerta ventana de compra | X10: Fuente del dato (Rendimiento) | Y10: Ubicación
A11: 0 | B11: Ejemplo: Reactivo X (no usar como dato real) | C11: Consumible de ensayo | E11: 15000 | F11: 1 | G11: =IF(OR(E11="",F11=""),"",E11*F11) -> 15000 | H11: 8 | J11: =IF(OR(G11="",I11=""),"",G11/I11) | K11: 4 | L11: 10 | M11: =IF(OR(E11="",H11="",K11="",L11=""),"",$B$4*(IF($O$10=$N$10,0,(E11-$N$10)/($O$10-$N$10)))+$B$5*(IF($Q$10=$P$10,0,(H11-$P$10)/($Q$10-$P$10)))+$B$6*((K11-1)/4)+$B$7*(IF($S$10=$R$10,0,(L11-$R$10)/($S$10-$R$10)))) -> 0.63244464 | O11: =IF(N11="","",SUMIFS($M$12:$M$79,$N$12:$N$79,"<="&N11)/SUM($M$12:$M$79)) | P11: =IF(N11="","",IF(N11<=ROUNDUP(0.2*COUNT($M$12:$M$79),0),"A",IF(N11<=ROUNDUP(0.5*COUNT($M$12:$M$79),0),"B","C"))) | Q11: =IF(P11="","",IF(P11="A",0.5,IF(P11="B",0.3,IF(P11="C",0.15,"")))) | R11: =IF(B11="","",SUMIFS('Registro de Ingresos'!$C:$C,'Registro de Ingresos'!$B:$B,B11)-SUMIFS('Registro de Egresos'!$C:$C,'Registro de Egresos'!$B:$B,B11)) -> 0 | S11: =IF(OR(H11="",L11="",Q11="",F11="",F11=0),"",CEILING((H11/30*L11)*(1+Q11),F11)) | T11: =IF(OR(R11="",S11=""),"",IF(R11<=S11,"REPONER AHORA","OK")) | U11: =IF(OR(R11="",S11="",H11=""),"",IF(H11=0,"",$E$3+MAX(0,(R11-S11)/(H11/30)))) | V11: =IF(U11="","",DAY(U11)) | W11: =IF(V11="","",IF(V11>20,"FUERA DE VENTANA","DENTRO DE VENTANA")) | Y11: Estante 3B | Z11: =IF(M11="","",M11+ROW()/100000000) -> 0.63244475
A12: 1 | B12: Cut Off Wheels, A303020, 300×32×2.0mm | C12: Consumible de metalografía | D12: Corte | E12: 6228 | G12: =IF(OR(E12="",F12=""),"",E12*F12) | J12: =IF(OR(G12="",I12=""),"",G12/I12) | M12: =IF(OR(E12="",H12="",K12="",L12=""),"",$B$4*(IF($O$10=$N$10,0,(E12-$N$10)/($O$10-$N$10)))+$B$5*(IF($Q$10=$P$10,0,(H12-$P$10)/($Q$10-$P$10)))+$B$6*((K12-1)/4)+$B$7*(IF($S$10=$R$10,0,(L12-$R$10)/($S$10-$R$10)))) | N12: =IF(Z12="","",RANK(Z12,$Z$12:$Z$79,0)) | O12: =IF(N12="","",SUMIFS($M$12:$M$79,$N$12:$N$79,"<="&N12)/SUM($M$12:$M$79)) | P12: =IF(N12="","",IF(N12<=ROUNDUP(0.2*COUNT($M$12:$M$79),0),"A",IF(N12<=ROUNDUP(0.5*COUNT($M$12:$M$79),0),"B","C"))) | Q12: =IF(P12="","",IF(P12="A",0.5,IF(P12="B",0.3,IF(P12="C",0.15,"")))) | R12: =IF(B12="","",SUMIFS('Registro de Ingresos'!$C:$C,'Registro de Ingresos'!$B:$B,B12)-SUMIFS('Registro de Egresos'!$C:$C,'Registro de Egresos'!$B:$B,B12)) -> 0 | S12: =IF(OR(H12="",L12="",Q12="",F12="",F12=0),"",CEILING((H12/30*L12)*(1+Q12),F12)) | T12: =IF(OR(R12="",S12=""),"",IF(R12<=S12,"REPONER AHORA","OK")) | U12: =IF(OR(R12="",S12="",H12=""),"",IF(H12=0,"",$E$3+MAX(0,(R12-S12)/(H12/30)))) | V12: =IF(U12="","",DAY(U12)) | W12: =IF(V12="","",IF(V12>20,"FUERA DE VENTANA","DENTRO DE VENTANA")) | Z12: =IF(M12="","",M12+ROW()/100000000)
A13: 2 | B13: Cut Off Wheels, A503020, 300×32×2.0mm | C13: Consumible de metalografía | D13: Corte | E13: 6228 | G13: =IF(OR(E13="",F13=""),"",E13*F13) | J13: =IF(OR(G13="",I13=""),"",G13/I13) | M13: =IF(OR(E13="",H13="",K13="",L13=""),"",$B$4*(IF($O$10=$N$10,0,(E13-$N$10)/($O$10-$N$10)))+$B$5*(IF($Q$10=$P$10,0,(H13-$P$10)/($Q$10-$P$10)))+$B$6*((K13-1)/4)+$B$7*(IF($S$10=$R$10,0,(L13-$R$10)/($S$10-$R$10)))) | N13: =IF(Z13="","",RANK(Z13,$Z$12:$Z$79,0)) | O13: =IF(N13="","",SUMIFS($M$12:$M$79,$N$12:$N$79,"<="&N13)/SUM($M$12:$M$79)) | P13: =IF(N13="","",IF(N13<=ROUNDUP(0.2*COUNT($M$12:$M$79),0),"A",IF(N13<=ROUNDUP(0.5*COUNT($M$12:$M$79),0),"B","C"))) | Q13: =IF(P13="","",IF(P13="A",0.5,IF(P13="B",0.3,IF(P13="C",0.15,"")))) | R13: =IF(B13="","",SUMIFS('Registro de Ingresos'!$C:$C,'Registro de Ingresos'!$B:$B,B13)-SUMIFS('Registro de Egresos'!$C:$C,'Registro de Egresos'!$B:$B,B13)) -> 0 | S13: =IF(OR(H13="",L13="",Q13="",F13="",F13=0),"",CEILING((H13/30*L13)*(1+Q13),F13)) | T13: =IF(OR(R13="",S13=""),"",IF(R13<=S13,"REPONER AHORA","OK")) | U13: =IF(OR(R13="",S13="",H13=""),"",IF(H13=0,"",$E$3+MAX(0,(R13-S13)/(H13/30)))) | V13: =IF(U13="","",DAY(U13)) | W13: =IF(V13="","",IF(V13>20,"FUERA DE VENTANA","DENTRO DE VENTANA")) | Z13: =IF(M13="","",M13+ROW()/100000000)
A14: 3 | B14: Cut Off Wheels, A603020, 300×32×2.0mm | C14: Consumible de metalografía | D14: Corte | E14: 7093 | G14: =IF(OR(E14="",F14=""),"",E14*F14) | J14: =IF(OR(G14="",I14=""),"",G14/I14) | M14: =IF(OR(E14="",H14="",K14="",L14=""),"",$B$4*(IF($O$10=$N$10,0,(E14-$N$10)/($O$10-$N$10)))+$B$5*(IF($Q$10=$P$10,0,(H14-$P$10)/($Q$10-$P$10)))+$B$6*((K14-1)/4)+$B$7*(IF($S$10=$R$10,0,(L14-$R$10)/($S$10-$R$10)))) | N14: =IF(Z14="","",RANK(Z14,$Z$12:$Z$79,0)) | O14: =IF(N14="","",SUMIFS($M$12:$M$79,$N$12:$N$79,"<="&N14)/SUM($M$12:$M$79)) | P14: =IF(N14="","",IF(N14<=ROUNDUP(0.2*COUNT($M$12:$M$79),0),"A",IF(N14<=ROUNDUP(0.5*COUNT($M$12:$M$79),0),"B","C"))) | Q14: =IF(P14="","",IF(P14="A",0.5,IF(P14="B",0.3,IF(P14="C",0.15,"")))) | R14: =IF(B14="","",SUMIFS('Registro de Ingresos'!$C:$C,'Registro de Ingresos'!$B:$B,B14)-SUMIFS('Registro de Egresos'!$C:$C,'Registro de Egresos'!$B:$B,B14)) -> 0 | S14: =IF(OR(H14="",L14="",Q14="",F14="",F14=0),"",CEILING((H14/30*L14)*(1+Q14),F14)) | T14: =IF(OR(R14="",S14=""),"",IF(R14<=S14,"REPONER AHORA","OK")) | U14: =IF(OR(R14="",S14="",H14=""),"",IF(H14=0,"",$E$3+MAX(0,(R14-S14)/(H14/30)))) | V14: =IF(U14="","",DAY(U14)) | W14: =IF(V14="","",IF(V14>20,"FUERA DE VENTANA","DENTRO DE VENTANA")) | Z14: =IF(M14="","",M14+ROW()/100000000)
A15: 4 | B15: Plastic Clip, Red, X-sample | C15: Consumible de metalografía | D15: Montaje | E15: 156 | G15: =IF(OR(E15="",F15=""),"",E15*F15) | J15: =IF(OR(G15="",I15=""),"",G15/I15) | M15: =IF(OR(E15="",H15="",K15="",L15=""),"",$B$4*(IF($O$10=$N$10,0,(E15-$N$10)/($O$10-$N$10)))+$B$5*(IF($Q$10=$P$10,0,(H15-$P$10)/($Q$10-$P$10)))+$B$6*((K15-1)/4)+$B$7*(IF($S$10=$R$10,0,(L15-$R$10)/($S$10-$R$10)))) | N15: =IF(Z15="","",RANK(Z15,$Z$12:$Z$79,0)) | O15: =IF(N15="","",SUMIFS($M$12:$M$79,$N$12:$N$79,"<="&N15)/SUM($M$12:$M$79)) | P15: =IF(N15="","",IF(N15<=ROUNDUP(0.2*COUNT($M$12:$M$79),0),"A",IF(N15<=ROUNDUP(0.5*COUNT($M$12:$M$79),0),"B","C"))) | Q15: =IF(P15="","",IF(P15="A",0.5,IF(P15="B",0.3,IF(P15="C",0.15,"")))) | R15: =IF(B15="","",SUMIFS('Registro de Ingresos'!$C:$C,'Registro de Ingresos'!$B:$B,B15)-SUMIFS('Registro de Egresos'!$C:$C,'Registro de Egresos'!$B:$B,B15)) -> 0 | S15: =IF(OR(H15="",L15="",Q15="",F15="",F15=0),"",CEILING((H15/30*L15)*(1+Q15),F15)) | T15: =IF(OR(R15="",S15=""),"",IF(R15<=S15,"REPONER AHORA","OK")) | U15: =IF(OR(R15="",S15="",H15=""),"",IF(H15=0,"",$E$3+MAX(0,(R15-S15)/(H15/30)))) | V15: =IF(U15="","",DAY(U15)) | W15: =IF(V15="","",IF(V15>20,"FUERA DE VENTANA","DENTRO DE VENTANA")) | Z15: =IF(M15="","",M15+ROW()/100000000)
A16: 5 | B16: Plastic Clip, Green, X-sample | C16: Consumible de metalografía | D16: Montaje | E16: 156 | G16: =IF(OR(E16="",F16=""),"",E16*F16) | J16: =IF(OR(G16="",I16=""),"",G16/I16) | M16: =IF(OR(E16="",H16="",K16="",L16=""),"",$B$4*(IF($O$10=$N$10,0,(E16-$N$10)/($O$10-$N$10)))+$B$5*(IF($Q$10=$P$10,0,(H16-$P$10)/($Q$10-$P$10)))+$B$6*((K16-1)/4)+$B$7*(IF($S$10=$R$10,0,(L16-$R$10)/($S$10-$R$10)))) | N16: =IF(Z16="","",RANK(Z16,$Z$12:$Z$79,0)) | O16: =IF(N16="","",SUMIFS($M$12:$M$79,$N$12:$N$79,"<="&N16)/SUM($M$12:$M$79)) | P16: =IF(N16="","",IF(N16<=ROUNDUP(0.2*COUNT($M$12:$M$79),0),"A",IF(N16<=ROUNDUP(0.5*COUNT($M$12:$M$79),0),"B","C"))) | Q16: =IF(P16="","",IF(P16="A",0.5,IF(P16="B",0.3,IF(P16="C",0.15,"")))) | R16: =IF(B16="","",SUMIFS('Registro de Ingresos'!$C:$C,'Registro de Ingresos'!$B:$B,B16)-SUMIFS('Registro de Egresos'!$C:$C,'Registro de Egresos'!$B:$B,B16)) -> 0 | S16: =IF(OR(H16="",L16="",Q16="",F16="",F16=0),"",CEILING((H16/30*L16)*(1+Q16),F16)) | T16: =IF(OR(R16="",S16=""),"",IF(R16<=S16,"REPONER AHORA","OK")) | U16: =IF(OR(R16="",S16="",H16=""),"",IF(H16=0,"",$E$3+MAX(0,(R16-S16)/(H16/30)))) | V16: =IF(U16="","",DAY(U16)) | W16: =IF(V16="","",IF(V16>20,"FUERA DE VENTANA","DENTRO DE VENTANA")) | Z16: =IF(M16="","",M16+ROW()/100000000)
A17: 6 | B17: Plastic Clip, White, X-sample | C17: Consumible de metalografía | D17: Montaje | E17: 156 | G17: =IF(OR(E17="",F17=""),"",E17*F17) | J17: =IF(OR(G17="",I17=""),"",G17/I17) | M17: =IF(OR(E17="",H17="",K17="",L17=""),"",$B$4*(IF($O$10=$N$10,0,(E17-$N$10)/($O$10-$N$10)))+$B$5*(IF($Q$10=$P$10,0,(H17-$P$10)/($Q$10-$P$10)))+$B$6*((K17-1)/4)+$B$7*(IF($S$10=$R$10,0,(L17-$R$10)/($S$10-$R$10)))) | N17: =IF(Z17="","",RANK(Z17,$Z$12:$Z$79,0)) | O17: =IF(N17="","",SUMIFS($M$12:$M$79,$N$12:$N$79,"<="&N17)/SUM($M$12:$M$79)) | P17: =IF(N17="","",IF(N17<=ROUNDUP(0.2*COUNT($M$12:$M$79),0),"A",IF(N17<=ROUNDUP(0.5*COUNT($M$12:$M$79),0),"B","C"))) | Q17: =IF(P17="","",IF(P17="A",0.5,IF(P17="B",0.3,IF(P17="C",0.15,"")))) | R17: =IF(B17="","",SUMIFS('Registro de Ingresos'!$C:$C,'Registro de Ingresos'!$B:$B,B17)-SUMIFS('Registro de Egresos'!$C:$C,'Registro de Egresos'!$B:$B,B17)) -> 0 | S17: =IF(OR(H17="",L17="",Q17="",F17="",F17=0),"",CEILING((H17/30*L17)*(1+Q17),F17)) | T17: =IF(OR(R17="",S17=""),"",IF(R17<=S17,"REPONER AHORA","OK")) | U17: =IF(OR(R17="",S17="",H17=""),"",IF(H17=0,"",$E$3+MAX(0,(R17-S17)/(H17/30)))) | V17: =IF(U17="","",DAY(U17)) | W17: =IF(V17="","",IF(V17>20,"FUERA DE VENTANA","DENTRO DE VENTANA")) | Z17: =IF(M17="","",M17+ROW()/100000000)
A18: 7 | B18: Sample Holder | C18: Consumible de metalografía | D18: Montaje | E18: 57090 | G18: =IF(OR(E18="",F18=""),"",E18*F18) | J18: =IF(OR(G18="",I18=""),"",G18/I18) | M18: =IF(OR(E18="",H18="",K18="",L18=""),"",$B$4*(IF($O$10=$N$10,0,(E18-$N$10)/($O$10-$N$10)))+$B$5*(IF($Q$10=$P$10,0,(H18-$P$10)/($Q$10-$P$10)))+$B$6*((K18-1)/4)+$B$7*(IF($S$10=$R$10,0,(L18-$R$10)/($S$10-$R$10)))) | N18: =IF(Z18="","",RANK(Z18,$Z$12:$Z$79,0)) | O18: =IF(N18="","",SUMIFS($M$12:$M$79,$N$12:$N$79,"<="&N18)/SUM($M$12:$M$79)) | P18: =IF(N18="","",IF(N18<=ROUNDUP(0.2*COUNT($M$12:$M$79),0),"A",IF(N18<=ROUNDUP(0.5*COUNT($M$12:$M$79),0),"B","C"))) | Q18: =IF(P18="","",IF(P18="A",0.5,IF(P18="B",0.3,IF(P18="C",0.15,"")))) | R18: =IF(B18="","",SUMIFS('Registro de Ingresos'!$C:$C,'Registro de Ingresos'!$B:$B,B18)-SUMIFS('Registro de Egresos'!$C:$C,'Registro de Egresos'!$B:$B,B18)) -> 0 | S18: =IF(OR(H18="",L18="",Q18="",F18="",F18=0),"",CEILING((H18/30*L18)*(1+Q18),F18)) | T18: =IF(OR(R18="",S18=""),"",IF(R18<=S18,"REPONER AHORA","OK")) | U18: =IF(OR(R18="",S18="",H18=""),"",IF(H18=0,"",$E$3+MAX(0,(R18-S18)/(H18/30)))) | V18: =IF(U18="","",DAY(U18)) | W18: =IF(V18="","",IF(V18>20,"FUERA DE VENTANA","DENTRO DE VENTANA")) | Z18: =IF(M18="","",M18+ROW()/100000000)
A19: 8 | B19: Abrasive Paper, Silicon Carbide, PSA, 250mm, 180# | C19: Consumible de metalografía | D19: Desbaste | E19: 606 | G19: =IF(OR(E19="",F19=""),"",E19*F19) | J19: =IF(OR(G19="",I19=""),"",G19/I19) | M19: =IF(OR(E19="",H19="",K19="",L19=""),"",$B$4*(IF($O$10=$N$10,0,(E19-$N$10)/($O$10-$N$10)))+$B$5*(IF($Q$10=$P$10,0,(H19-$P$10)/($Q$10-$P$10)))+$B$6*((K19-1)/4)+$B$7*(IF($S$10=$R$10,0,(L19-$R$10)/($S$10-$R$10)))) | N19: =IF(Z19="","",RANK(Z19,$Z$12:$Z$79,0)) | O19: =IF(N19="","",SUMIFS($M$12:$M$79,$N$12:$N$79,"<="&N19)/SUM($M$12:$M$79)) | P19: =IF(N19="","",IF(N19<=ROUNDUP(0.2*COUNT($M$12:$M$79),0),"A",IF(N19<=ROUNDUP(0.5*COUNT($M$12:$M$79),0),"B","C"))) | Q19: =IF(P19="","",IF(P19="A",0.5,IF(P19="B",0.3,IF(P19="C",0.15,"")))) | R19: =IF(B19="","",SUMIFS('Registro de Ingresos'!$C:$C,'Registro de Ingresos'!$B:$B,B19)-SUMIFS('Registro de Egresos'!$C:$C,'Registro de Egresos'!$B:$B,B19)) -> 0 | S19: =IF(OR(H19="",L19="",Q19="",F19="",F19=0),"",CEILING((H19/30*L19)*(1+Q19),F19)) | T19: =IF(OR(R19="",S19=""),"",IF(R19<=S19,"REPONER AHORA","OK")) | U19: =IF(OR(R19="",S19="",H19=""),"",IF(H19=0,"",$E$3+MAX(0,(R19-S19)/(H19/30)))) | V19: =IF(U19="","",DAY(U19)) | W19: =IF(V19="","",IF(V19>20,"FUERA DE VENTANA","DENTRO DE VENTANA")) | Z19: =IF(M19="","",M19+ROW()/100000000)
A20: 9 | B20: Abrasive Paper, Silicon Carbide, PSA, 250mm, 400# | C20: Consumible de metalografía | D20: Desbaste | E20: 606 | G20: =IF(OR(E20="",F20=""),"",E20*F20) | J20: =IF(OR(G20="",I20=""),"",G20/I20) | M20: =IF(OR(E20="",H20="",K20="",L20=""),"",$B$4*(IF($O$10=$N$10,0,(E20-$N$10)/($O$10-$N$10)))+$B$5*(IF($Q$10=$P$10,0,(H20-$P$10)/($Q$10-$P$10)))+$B$6*((K20-1)/4)+$B$7*(IF($S$10=$R$10,0,(L20-$R$10)/($S$10-$R$10)))) | N20: =IF(Z20="","",RANK(Z20,$Z$12:$Z$79,0)) | O20: =IF(N20="","",SUMIFS($M$12:$M$79,$N$12:$N$79,"<="&N20)/SUM($M$12:$M$79)) | P20: =IF(N20="","",IF(N20<=ROUNDUP(0.2*COUNT($M$12:$M$79),0),"A",IF(N20<=ROUNDUP(0.5*COUNT($M$12:$M$79),0),"B","C"))) | Q20: =IF(P20="","",IF(P20="A",0.5,IF(P20="B",0.3,IF(P20="C",0.15,"")))) | R20: =IF(B20="","",SUMIFS('Registro de Ingresos'!$C:$C,'Registro de Ingresos'!$B:$B,B20)-SUMIFS('Registro de Egresos'!$C:$C,'Registro de Egresos'!$B:$B,B20)) -> 0 | S20: =IF(OR(H20="",L20="",Q20="",F20="",F20=0),"",CEILING((H20/30*L20)*(1+Q20),F20)) | T20: =IF(OR(R20="",S20=""),"",IF(R20<=S20,"REPONER AHORA","OK")) | U20: =IF(OR(R20="",S20="",H20=""),"",IF(H20=0,"",$E$3+MAX(0,(R20-S20)/(H20/30)))) | V20: =IF(U20="","",DAY(U20)) | W20: =IF(V20="","",IF(V20>20,"FUERA DE VENTANA","DENTRO DE VENTANA")) | Z20: =IF(M20="","",M20+ROW()/100000000)
A21: 10 | B21: Abrasive Paper, Silicon Carbide, PSA, 250mm, 800# | C21: Consumible de metalografía | D21: Desbaste | E21: 606 | G21: =IF(OR(E21="",F21=""),"",E21*F21) | J21: =IF(OR(G21="",I21=""),"",G21/I21) | M21: =IF(OR(E21="",H21="",K21="",L21=""),"",$B$4*(IF($O$10=$N$10,0,(E21-$N$10)/($O$10-$N$10)))+$B$5*(IF($Q$10=$P$10,0,(H21-$P$10)/($Q$10-$P$10)))+$B$6*((K21-1)/4)+$B$7*(IF($S$10=$R$10,0,(L21-$R$10)/($S$10-$R$10)))) | N21: =IF(Z21="","",RANK(Z21,$Z$12:$Z$79,0)) | O21: =IF(N21="","",SUMIFS($M$12:$M$79,$N$12:$N$79,"<="&N21)/SUM($M$12:$M$79)) | P21: =IF(N21="","",IF(N21<=ROUNDUP(0.2*COUNT($M$12:$M$79),0),"A",IF(N21<=ROUNDUP(0.5*COUNT($M$12:$M$79),0),"B","C"))) | Q21: =IF(P21="","",IF(P21="A",0.5,IF(P21="B",0.3,IF(P21="C",0.15,"")))) | R21: =IF(B21="","",SUMIFS('Registro de Ingresos'!$C:$C,'Registro de Ingresos'!$B:$B,B21)-SUMIFS('Registro de Egresos'!$C:$C,'Registro de Egresos'!$B:$B,B21)) -> 0 | S21: =IF(OR(H21="",L21="",Q21="",F21="",F21=0),"",CEILING((H21/30*L21)*(1+Q21),F21)) | T21: =IF(OR(R21="",S21=""),"",IF(R21<=S21,"REPONER AHORA","OK")) | U21: =IF(OR(R21="",S21="",H21=""),"",IF(H21=0,"",$E$3+MAX(0,(R21-S21)/(H21/30)))) | V21: =IF(U21="","",DAY(U21)) | W21: =IF(V21="","",IF(V21>20,"FUERA DE VENTANA","DENTRO DE VENTANA")) | Z21: =IF(M21="","",M21+ROW()/100000000)
A22: 11 | B22: Abrasive Paper, Silicon Carbide, PSA, 250mm, 1200# | C22: Consumible de metalografía | D22: Desbaste | E22: 606 | G22: =IF(OR(E22="",F22=""),"",E22*F22) | J22: =IF(OR(G22="",I22=""),"",G22/I22) | M22: =IF(OR(E22="",H22="",K22="",L22=""),"",$B$4*(IF($O$10=$N$10,0,(E22-$N$10)/($O$10-$N$10)))+$B$5*(IF($Q$10=$P$10,0,(H22-$P$10)/($Q$10-$P$10)))+$B$6*((K22-1)/4)+$B$7*(IF($S$10=$R$10,0,(L22-$R$10)/($S$10-$R$10)))) | N22: =IF(Z22="","",RANK(Z22,$Z$12:$Z$79,0)) | O22: =IF(N22="","",SUMIFS($M$12:$M$79,$N$12:$N$79,"<="&N22)/SUM($M$12:$M$79)) | P22: =IF(N22="","",IF(N22<=ROUNDUP(0.2*COUNT($M$12:$M$79),0),"A",IF(N22<=ROUNDUP(0.5*COUNT($M$12:$M$79),0),"B","C"))) | Q22: =IF(P22="","",IF(P22="A",0.5,IF(P22="B",0.3,IF(P22="C",0.15,"")))) | R22: =IF(B22="","",SUMIFS('Registro de Ingresos'!$C:$C,'Registro de Ingresos'!$B:$B,B22)-SUMIFS('Registro de Egresos'!$C:$C,'Registro de Egresos'!$B:$B,B22)) -> 0 | S22: =IF(OR(H22="",L22="",Q22="",F22="",F22=0),"",CEILING((H22/30*L22)*(1+Q22),F22)) | T22: =IF(OR(R22="",S22=""),"",IF(R22<=S22,"REPONER AHORA","OK")) | U22: =IF(OR(R22="",S22="",H22=""),"",IF(H22=0,"",$E$3+MAX(0,(R22-S22)/(H22/30)))) | V22: =IF(U22="","",DAY(U22)) | W22: =IF(V22="","",IF(V22>20,"FUERA DE VENTANA","DENTRO DE VENTANA")) | Z22: =IF(M22="","",M22+ROW()/100000000)
A23: 12 | B23: Abrasive Paper, Silicon Carbide, PSA, 250mm, 2400# | C23: Consumible de metalografía | D23: Desbaste | E23: 2439 | G23: =IF(OR(E23="",F23=""),"",E23*F23) | J23: =IF(OR(G23="",I23=""),"",G23/I23) | M23: =IF(OR(E23="",H23="",K23="",L23=""),"",$B$4*(IF($O$10=$N$10,0,(E23-$N$10)/($O$10-$N$10)))+$B$5*(IF($Q$10=$P$10,0,(H23-$P$10)/($Q$10-$P$10)))+$B$6*((K23-1)/4)+$B$7*(IF($S$10=$R$10,0,(L23-$R$10)/($S$10-$R$10)))) | N23: =IF(Z23="","",RANK(Z23,$Z$12:$Z$79,0)) | O23: =IF(N23="","",SUMIFS($M$12:$M$79,$N$12:$N$79,"<="&N23)/SUM($M$12:$M$79)) | P23: =IF(N23="","",IF(N23<=ROUNDUP(0.2*COUNT($M$12:$M$79),0),"A",IF(N23<=ROUNDUP(0.5*COUNT($M$12:$M$79),0),"B","C"))) | Q23: =IF(P23="","",IF(P23="A",0.5,IF(P23="B",0.3,IF(P23="C",0.15,"")))) | R23: =IF(B23="","",SUMIFS('Registro de Ingresos'!$C:$C,'Registro de Ingresos'!$B:$B,B23)-SUMIFS('Registro de Egresos'!$C:$C,'Registro de Egresos'!$B:$B,B23)) -> 0 | S23: =IF(OR(H23="",L23="",Q23="",F23="",F23=0),"",CEILING((H23/30*L23)*(1+Q23),F23)) | T23: =IF(OR(R23="",S23=""),"",IF(R23<=S23,"REPONER AHORA","OK")) | U23: =IF(OR(R23="",S23="",H23=""),"",IF(H23=0,"",$E$3+MAX(0,(R23-S23)/(H23/30)))) | V23: =IF(U23="","",DAY(U23)) | W23: =IF(V23="","",IF(V23>20,"FUERA DE VENTANA","DENTRO DE VENTANA")) | Z23: =IF(M23="","",M23+ROW()/100000000)
... A40: 29 | B40: Guantes de latex talla M | C40: Consumible de metalografía | D40: EPP | E40: 41 | G40: =IF(OR(E40="",F40=""),"",E40*F40) | J40: =IF(OR(G40="",I40=""),"",G40/I40) | M40: =IF(OR(E40="",H40="",K40="",L40=""),"",$B$4*(IF($O$10=$N$10,0,(E40-$N$10)/($O$10-$N$10)))+$B$5*(IF($Q$10=$P$10,0,(H40-$P$10)/($Q$10-$P$10)))+$B$6*((K40-1)/4)+$B$7*(IF($S$10=$R$10,0,(L40-$R$10)/($S$10-$R$10)))) | N40: =IF(Z40="","",RANK(Z40,$Z$12:$Z$79,0)) | O40: =IF(N40="","",SUMIFS($M$12:$M$79,$N$12:$N$79,"<="&N40)/SUM($M$12:$M$79)) | P40: =IF(N40="","",IF(N40<=ROUNDUP(0.2*COUNT($M$12:$M$79),0),"A",IF(N40<=ROUNDUP(0.5*COUNT($M$12:$M$79),0),"B","C"))) | Q40: =IF(P40="","",IF(P40="A",0.5,IF(P40="B",0.3,IF(P40="C",0.15,"")))) | R40: =IF(B40="","",SUMIFS('Registro de Ingresos'!$C:$C,'Registro de Ingresos'!$B:$B,B40)-SUMIFS('Registro de Egresos'!$C:$C,'Registro de Egresos'!$B:$B,B40)) -> 0 | S40: =IF(OR(H40="",L40="",Q40="",F40="",F40=0),"",CEILING((H40/30*L40)*(1+Q40),F40)) | T40: =IF(OR(R40="",S40=""),"",IF(R40<=S40,"REPONER AHORA","OK")) | U40: =IF(OR(R40="",S40="",H40=""),"",IF(H40=0,"",$E$3+MAX(0,(R40-S40)/(H40/30)))) | V40: =IF(U40="","",DAY(U40)) | W40: =IF(V40="","",IF(V40>20,"FUERA DE VENTANA","DENTRO DE VENTANA")) | Z40: =IF(M40="","",M40+ROW()/100000000)
A41: 30 | G41: =IF(OR(E41="",F41=""),"",E41*F41) | J41: =IF(OR(G41="",I41=""),"",G41/I41) | M41: =IF(OR(E41="",H41="",K41="",L41=""),"",$B$4*(IF($O$10=$N$10,0,(E41-$N$10)/($O$10-$N$10)))+$B$5*(IF($Q$10=$P$10,0,(H41-$P$10)/($Q$10-$P$10)))+$B$6*((K41-1)/4)+$B$7*(IF($S$10=$R$10,0,(L41-$R$10)/($S$10-$R$10)))) | N41: =IF(Z41="","",RANK(Z41,$Z$12:$Z$79,0)) | O41: =IF(N41="","",SUMIFS($M$12:$M$79,$N$12:$N$79,"<="&N41)/SUM($M$12:$M$79)) | P41: =IF(N41="","",IF(N41<=ROUNDUP(0.2*COUNT($M$12:$M$79),0),"A",IF(N41<=ROUNDUP(0.5*COUNT($M$12:$M$79),0),"B","C"))) | Q41: =IF(P41="","",IF(P41="A",0.5,IF(P41="B",0.3,IF(P41="C",0.15,"")))) | R41: =IF(B41="","",SUMIFS('Registro de Ingresos'!$C:$C,'Registro de Ingresos'!$B:$B,B41)-SUMIFS('Registro de Egresos'!$C:$C,'Registro de Egresos'!$B:$B,B41)) | S41: =IF(OR(H41="",L41="",Q41="",F41="",F41=0),"",CEILING((H41/30*L41)*(1+Q41),F41)) | T41: =IF(OR(R41="",S41=""),"",IF(R41<=S41,"REPONER AHORA","OK")) | U41: =IF(OR(R41="",S41="",H41=""),"",IF(H41=0,"",$E$3+MAX(0,(R41-S41)/(H41/30)))) | V41: =IF(U41="","",DAY(U41)) | W41: =IF(V41="","",IF(V41>20,"FUERA DE VENTANA","DENTRO DE VENTANA")) | Z41: =IF(M41="","",M41+ROW()/100000000)
A42: 31 | G42: =IF(OR(E42="",F42=""),"",E42*F42) | J42: =IF(OR(G42="",I42=""),"",G42/I42) | M42: =IF(OR(E42="",H42="",K42="",L42=""),"",$B$4*(IF($O$10=$N$10,0,(E42-$N$10)/($O$10-$N$10)))+$B$5*(IF($Q$10=$P$10,0,(H42-$P$10)/($Q$10-$P$10)))+$B$6*((K42-1)/4)+$B$7*(IF($S$10=$R$10,0,(L42-$R$10)/($S$10-$R$10)))) | N42: =IF(Z42="","",RANK(Z42,$Z$12:$Z$79,0)) | O42: =IF(N42="","",SUMIFS($M$12:$M$79,$N$12:$N$79,"<="&N42)/SUM($M$12:$M$79)) | P42: =IF(N42="","",IF(N42<=ROUNDUP(0.2*COUNT($M$12:$M$79),0),"A",IF(N42<=ROUNDUP(0.5*COUNT($M$12:$M$79),0),"B","C"))) | Q42: =IF(P42="","",IF(P42="A",0.5,IF(P42="B",0.3,IF(P42="C",0.15,"")))) | R42: =IF(B42="","",SUMIFS('Registro de Ingresos'!$C:$C,'Registro de Ingresos'!$B:$B,B42)-SUMIFS('Registro de Egresos'!$C:$C,'Registro de Egresos'!$B:$B,B42)) | S42: =IF(OR(H42="",L42="",Q42="",F42="",F42=0),"",CEILING((H42/30*L42)*(1+Q42),F42)) | T42: =IF(OR(R42="",S42=""),"",IF(R42<=S42,"REPONER AHORA","OK")) | U42: =IF(OR(R42="",S42="",H42=""),"",IF(H42=0,"",$E$3+MAX(0,(R42-S42)/(H42/30)))) | V42: =IF(U42="","",DAY(U42)) | W42: =IF(V42="","",IF(V42>20,"FUERA DE VENTANA","DENTRO DE VENTANA")) | Z42: =IF(M42="","",M42+ROW()/100000000)
A43: 32 | G43: =IF(OR(E43="",F43=""),"",E43*F43) | J43: =IF(OR(G43="",I43=""),"",G43/I43) | M43: =IF(OR(E43="",H43="",K43="",L43=""),"",$B$4*(IF($O$10=$N$10,0,(E43-$N$10)/($O$10-$N$10)))+$B$5*(IF($Q$10=$P$10,0,(H43-$P$10)/($Q$10-$P$10)))+$B$6*((K43-1)/4)+$B$7*(IF($S$10=$R$10,0,(L43-$R$10)/($S$10-$R$10)))) | N43: =IF(Z43="","",RANK(Z43,$Z$12:$Z$79,0)) | O43: =IF(N43="","",SUMIFS($M$12:$M$79,$N$12:$N$79,"<="&N43)/SUM($M$12:$M$79)) | P43: =IF(N43="","",IF(N43<=ROUNDUP(0.2*COUNT($M$12:$M$79),0),"A",IF(N43<=ROUNDUP(0.5*COUNT($M$12:$M$79),0),"B","C"))) | Q43: =IF(P43="","",IF(P43="A",0.5,IF(P43="B",0.3,IF(P43="C",0.15,"")))) | R43: =IF(B43="","",SUMIFS('Registro de Ingresos'!$C:$C,'Registro de Ingresos'!$B:$B,B43)-SUMIFS('Registro de Egresos'!$C:$C,'Registro de Egresos'!$B:$B,B43)) | S43: =IF(OR(H43="",L43="",Q43="",F43="",F43=0),"",CEILING((H43/30*L43)*(1+Q43),F43)) | T43: =IF(OR(R43="",S43=""),"",IF(R43<=S43,"REPONER AHORA","OK")) | U43: =IF(OR(R43="",S43="",H43=""),"",IF(H43=0,"",$E$3+MAX(0,(R43-S43)/(H43/30)))) | V43: =IF(U43="","",DAY(U43)) | W43: =IF(V43="","",IF(V43>20,"FUERA DE VENTANA","DENTRO DE VENTANA")) | Z43: =IF(M43="","",M43+ROW()/100000000)
A44: 33 | G44: =IF(OR(E44="",F44=""),"",E44*F44) | J44: =IF(OR(G44="",I44=""),"",G44/I44) | M44: =IF(OR(E44="",H44="",K44="",L44=""),"",$B$4*(IF($O$10=$N$10,0,(E44-$N$10)/($O$10-$N$10)))+$B$5*(IF($Q$10=$P$10,0,(H44-$P$10)/($Q$10-$P$10)))+$B$6*((K44-1)/4)+$B$7*(IF($S$10=$R$10,0,(L44-$R$10)/($S$10-$R$10)))) | N44: =IF(Z44="","",RANK(Z44,$Z$12:$Z$79,0)) | O44: =IF(N44="","",SUMIFS($M$12:$M$79,$N$12:$N$79,"<="&N44)/SUM($M$12:$M$79)) | P44: =IF(N44="","",IF(N44<=ROUNDUP(0.2*COUNT($M$12:$M$79),0),"A",IF(N44<=ROUNDUP(0.5*COUNT($M$12:$M$79),0),"B","C"))) | Q44: =IF(P44="","",IF(P44="A",0.5,IF(P44="B",0.3,IF(P44="C",0.15,"")))) | R44: =IF(B44="","",SUMIFS('Registro de Ingresos'!$C:$C,'Registro de Ingresos'!$B:$B,B44)-SUMIFS('Registro de Egresos'!$C:$C,'Registro de Egresos'!$B:$B,B44)) | S44: =IF(OR(H44="",L44="",Q44="",F44="",F44=0),"",CEILING((H44/30*L44)*(1+Q44),F44)) | T44: =IF(OR(R44="",S44=""),"",IF(R44<=S44,"REPONER AHORA","OK")) | U44: =IF(OR(R44="",S44="",H44=""),"",IF(H44=0,"",$E$3+MAX(0,(R44-S44)/(H44/30)))) | V44: =IF(U44="","",DAY(U44)) | W44: =IF(V44="","",IF(V44>20,"FUERA DE VENTANA","DENTRO DE VENTANA")) | Z44: =IF(M44="","",M44+ROW()/100000000)
A45: 34 | G45: =IF(OR(E45="",F45=""),"",E45*F45) | J45: =IF(OR(G45="",I45=""),"",G45/I45) | M45: =IF(OR(E45="",H45="",K45="",L45=""),"",$B$4*(IF($O$10=$N$10,0,(E45-$N$10)/($O$10-$N$10)))+$B$5*(IF($Q$10=$P$10,0,(H45-$P$10)/($Q$10-$P$10)))+$B$6*((K45-1)/4)+$B$7*(IF($S$10=$R$10,0,(L45-$R$10)/($S$10-$R$10)))) | N45: =IF(Z45="","",RANK(Z45,$Z$12:$Z$79,0)) | O45: =IF(N45="","",SUMIFS($M$12:$M$79,$N$12:$N$79,"<="&N45)/SUM($M$12:$M$79)) | P45: =IF(N45="","",IF(N45<=ROUNDUP(0.2*COUNT($M$12:$M$79),0),"A",IF(N45<=ROUNDUP(0.5*COUNT($M$12:$M$79),0),"B","C"))) | Q45: =IF(P45="","",IF(P45="A",0.5,IF(P45="B",0.3,IF(P45="C",0.15,"")))) | R45: =IF(B45="","",SUMIFS('Registro de Ingresos'!$C:$C,'Registro de Ingresos'!$B:$B,B45)-SUMIFS('Registro de Egresos'!$C:$C,'Registro de Egresos'!$B:$B,B45)) | S45: =IF(OR(H45="",L45="",Q45="",F45="",F45=0),"",CEILING((H45/30*L45)*(1+Q45),F45)) | T45: =IF(OR(R45="",S45=""),"",IF(R45<=S45,"REPONER AHORA","OK")) | U45: =IF(OR(R45="",S45="",H45=""),"",IF(H45=0,"",$E$3+MAX(0,(R45-S45)/(H45/30)))) | V45: =IF(U45="","",DAY(U45)) | W45: =IF(V45="","",IF(V45>20,"FUERA DE VENTANA","DENTRO DE VENTANA")) | Z45: =IF(M45="","",M45+ROW()/100000000)
A46: 35 | G46: =IF(OR(E46="",F46=""),"",E46*F46) | J46: =IF(OR(G46="",I46=""),"",G46/I46) | M46: =IF(OR(E46="",H46="",K46="",L46=""),"",$B$4*(IF($O$10=$N$10,0,(E46-$N$10)/($O$10-$N$10)))+$B$5*(IF($Q$10=$P$10,0,(H46-$P$10)/($Q$10-$P$10)))+$B$6*((K46-1)/4)+$B$7*(IF($S$10=$R$10,0,(L46-$R$10)/($S$10-$R$10)))) | N46: =IF(Z46="","",RANK(Z46,$Z$12:$Z$79,0)) | O46: =IF(N46="","",SUMIFS($M$12:$M$79,$N$12:$N$79,"<="&N46)/SUM($M$12:$M$79)) | P46: =IF(N46="","",IF(N46<=ROUNDUP(0.2*COUNT($M$12:$M$79),0),"A",IF(N46<=ROUNDUP(0.5*COUNT($M$12:$M$79),0),"B","C"))) | Q46: =IF(P46="","",IF(P46="A",0.5,IF(P46="B",0.3,IF(P46="C",0.15,"")))) | R46: =IF(B46="","",SUMIFS('Registro de Ingresos'!$C:$C,'Registro de Ingresos'!$B:$B,B46)-SUMIFS('Registro de Egresos'!$C:$C,'Registro de Egresos'!$B:$B,B46)) | S46: =IF(OR(H46="",L46="",Q46="",F46="",F46=0),"",CEILING((H46/30*L46)*(1+Q46),F46)) | T46: =IF(OR(R46="",S46=""),"",IF(R46<=S46,"REPONER AHORA","OK")) | U46: =IF(OR(R46="",S46="",H46=""),"",IF(H46=0,"",$E$3+MAX(0,(R46-S46)/(H46/30)))) | V46: =IF(U46="","",DAY(U46)) | W46: =IF(V46="","",IF(V46>20,"FUERA DE VENTANA","DENTRO DE VENTANA")) | Z46: =IF(M46="","",M46+ROW()/100000000)
A47: 36 | G47: =IF(OR(E47="",F47=""),"",E47*F47) | J47: =IF(OR(G47="",I47=""),"",G47/I47) | M47: =IF(OR(E47="",H47="",K47="",L47=""),"",$B$4*(IF($O$10=$N$10,0,(E47-$N$10)/($O$10-$N$10)))+$B$5*(IF($Q$10=$P$10,0,(H47-$P$10)/($Q$10-$P$10)))+$B$6*((K47-1)/4)+$B$7*(IF($S$10=$R$10,0,(L47-$R$10)/($S$10-$R$10)))) | N47: =IF(Z47="","",RANK(Z47,$Z$12:$Z$79,0)) | O47: =IF(N47="","",SUMIFS($M$12:$M$79,$N$12:$N$79,"<="&N47)/SUM($M$12:$M$79)) | P47: =IF(N47="","",IF(N47<=ROUNDUP(0.2*COUNT($M$12:$M$79),0),"A",IF(N47<=ROUNDUP(0.5*COUNT($M$12:$M$79),0),"B","C"))) | Q47: =IF(P47="","",IF(P47="A",0.5,IF(P47="B",0.3,IF(P47="C",0.15,"")))) | R47: =IF(B47="","",SUMIFS('Registro de Ingresos'!$C:$C,'Registro de Ingresos'!$B:$B,B47)-SUMIFS('Registro de Egresos'!$C:$C,'Registro de Egresos'!$B:$B,B47)) | S47: =IF(OR(H47="",L47="",Q47="",F47="",F47=0),"",CEILING((H47/30*L47)*(1+Q47),F47)) | T47: =IF(OR(R47="",S47=""),"",IF(R47<=S47,"REPONER AHORA","OK")) | U47: =IF(OR(R47="",S47="",H47=""),"",IF(H47=0,"",$E$3+MAX(0,(R47-S47)/(H47/30)))) | V47: =IF(U47="","",DAY(U47)) | W47: =IF(V47="","",IF(V47>20,"FUERA DE VENTANA","DENTRO DE VENTANA")) | Z47: =IF(M47="","",M47+ROW()/100000000)
A48: 37 | B48: Sierra bimetal 1" 4-6 E0,9 | C48: Rendimiento múltiple (herramienta) | D48: Corte | E48: 36860.25 | F48: 1 | G48: =IF(OR(E48="",F48=""),"",E48*F48) -> 36860.25 | H48: 20 | I48: 40 | J48: =IF(OR(G48="",I48=""),"",G48/I48) -> 921.50625 | K48: 5 | L48: 5 | M48: =IF(OR(E48="",H48="",K48="",L48=""),"",$B$4*(IF($O$10=$N$10,0,(E48-$N$10)/($O$10-$N$10)))+$B$5*(IF($Q$10=$P$10,0,(H48-$P$10)/($Q$10-$P$10)))+$B$6*((K48-1)/4)+$B$7*(IF($S$10=$R$10,0,(L48-$R$10)/($S$10-$R$10)))) -> 0.92678373 | N48: =IF(Z48="","",RANK(Z48,$Z$12:$Z$79,0)) -> 1 | O48: =IF(N48="","",SUMIFS($M$12:$M$79,$N$12:$N$79,"<="&N48)/SUM($M$12:$M$79)) -> 0.21889914 | P48: =IF(N48="","",IF(N48<=ROUNDUP(0.2*COUNT($M$12:$M$79),0),"A",IF(N48<=ROUNDUP(0.5*COUNT($M$12:$M$79),0),"B","C"))) -> A | Q48: =IF(P48="","",IF(P48="A",0.5,IF(P48="B",0.3,IF(P48="C",0.15,"")))) -> 0.5 | R48: =IF(B48="","",SUMIFS('Registro de Ingresos'!$C:$C,'Registro de Ingresos'!$B:$B,B48)-SUMIFS('Registro de Egresos'!$C:$C,'Registro de Egresos'!$B:$B,B48)) -> 0 | S48: =IF(OR(H48="",L48="",Q48="",F48="",F48=0),"",CEILING((H48/30*L48)*(1+Q48),F48)) -> 5 | T48: =IF(OR(R48="",S48=""),"",IF(R48<=S48,"REPONER AHORA","OK")) -> REPONER AHORA | U48: =IF(OR(R48="",S48="",H48=""),"",IF(H48=0,"",$E$3+MAX(0,(R48-S48)/(H48/30)))) -> 46265 | V48: =IF(U48="","",DAY(U48)) -> 31 | W48: =IF(V48="","",IF(V48>20,"FUERA DE VENTANA","DENTRO DE VENTANA")) -> FUERA DE VENTANA | Z48: =IF(M48="","",M48+ROW()/100000000) -> 0.92678421
A49: 38 | B49: Sierra bimetal 1" 5-7 E0,9 | C49: Rendimiento múltiple (herramienta) | D49: Corte | E49: 37859.85 | F49: 1 | G49: =IF(OR(E49="",F49=""),"",E49*F49) -> 37859.85 | H49: 5 | I49: 40 | J49: =IF(OR(G49="",I49=""),"",G49/I49) -> 946.49625 | K49: 5 | L49: 5 | M49: =IF(OR(E49="",H49="",K49="",L49=""),"",$B$4*(IF($O$10=$N$10,0,(E49-$N$10)/($O$10-$N$10)))+$B$5*(IF($Q$10=$P$10,0,(H49-$P$10)/($Q$10-$P$10)))+$B$6*((K49-1)/4)+$B$7*(IF($S$10=$R$10,0,(L49-$R$10)/($S$10-$R$10)))) -> 0.69145398 | N49: =IF(Z49="","",RANK(Z49,$Z$12:$Z$79,0)) -> 2 | O49: =IF(N49="","",SUMIFS($M$12:$M$79,$N$12:$N$79,"<="&N49)/SUM($M$12:$M$79)) -> 0.38221522 | P49: =IF(N49="","",IF(N49<=ROUNDUP(0.2*COUNT($M$12:$M$79),0),"A",IF(N49<=ROUNDUP(0.5*COUNT($M$12:$M$79),0),"B","C"))) -> A | Q49: =IF(P49="","",IF(P49="A",0.5,IF(P49="B",0.3,IF(P49="C",0.15,"")))) -> 0.5 | R49: =IF(B49="","",SUMIFS('Registro de Ingresos'!$C:$C,'Registro de Ingresos'!$B:$B,B49)-SUMIFS('Registro de Egresos'!$C:$C,'Registro de Egresos'!$B:$B,B49)) -> 0 | S49: =IF(OR(H49="",L49="",Q49="",F49="",F49=0),"",CEILING((H49/30*L49)*(1+Q49),F49)) -> 2 | T49: =IF(OR(R49="",S49=""),"",IF(R49<=S49,"REPONER AHORA","OK")) -> REPONER AHORA | U49: =IF(OR(R49="",S49="",H49=""),"",IF(H49=0,"",$E$3+MAX(0,(R49-S49)/(H49/30)))) -> 46265 | V49: =IF(U49="","",DAY(U49)) -> 31 | W49: =IF(V49="","",IF(V49>20,"FUERA DE VENTANA","DENTRO DE VENTANA")) -> FUERA DE VENTANA | Z49: =IF(M49="","",M49+ROW()/100000000) -> 0.69145447
A50: 39 | B50: Sierra bimetal 1" 3-4 E0,9 | C50: Rendimiento múltiple (herramienta) | D50: Corte | E50: 36860.25 | F50: 1 | G50: =IF(OR(E50="",F50=""),"",E50*F50) -> 36860.25 | H50: 5 | I50: 20 | J50: =IF(OR(G50="",I50=""),"",G50/I50) -> 1843.0125 | K50: 5 | L50: 5 | M50: =IF(OR(E50="",H50="",K50="",L50=""),"",$B$4*(IF($O$10=$N$10,0,(E50-$N$10)/($O$10-$N$10)))+$B$5*(IF($Q$10=$P$10,0,(H50-$P$10)/($Q$10-$P$10)))+$B$6*((K50-1)/4)+$B$7*(IF($S$10=$R$10,0,(L50-$R$10)/($S$10-$R$10)))) -> 0.69116626 | N50: =IF(Z50="","",RANK(Z50,$Z$12:$Z$79,0)) -> 3 | O50: =IF(N50="","",SUMIFS($M$12:$M$79,$N$12:$N$79,"<="&N50)/SUM($M$12:$M$79)) -> 0.54546335 | P50: =IF(N50="","",IF(N50<=ROUNDUP(0.2*COUNT($M$12:$M$79),0),"A",IF(N50<=ROUNDUP(0.5*COUNT($M$12:$M$79),0),"B","C"))) -> A | Q50: =IF(P50="","",IF(P50="A",0.5,IF(P50="B",0.3,IF(P50="C",0.15,"")))) -> 0.5 | R50: =IF(B50="","",SUMIFS('Registro de Ingresos'!$C:$C,'Registro de Ingresos'!$B:$B,B50)-SUMIFS('Registro de Egresos'!$C:$C,'Registro de Egresos'!$B:$B,B50)) -> 0 | S50: =IF(OR(H50="",L50="",Q50="",F50="",F50=0),"",CEILING((H50/30*L50)*(1+Q50),F50)) -> 2 | T50: =IF(OR(R50="",S50=""),"",IF(R50<=S50,"REPONER AHORA","OK")) -> REPONER AHORA | U50: =IF(OR(R50="",S50="",H50=""),"",IF(H50=0,"",$E$3+MAX(0,(R50-S50)/(H50/30)))) -> 46265 | V50: =IF(U50="","",DAY(U50)) -> 31 | W50: =IF(V50="","",IF(V50>20,"FUERA DE VENTANA","DENTRO DE VENTANA")) -> FUERA DE VENTANA | Z50: =IF(M50="","",M50+ROW()/100000000) -> 0.69116676
A51: 40 | B51: Correa motor A-37 | C51: Consumible de ensayo | E51: 9460.5 | F51: 1 | G51: =IF(OR(E51="",F51=""),"",E51*F51) -> 9460.5 | H51: 0.1 | J51: =IF(OR(G51="",I51=""),"",G51/I51) | M51: =IF(OR(E51="",H51="",K51="",L51=""),"",$B$4*(IF($O$10=$N$10,0,(E51-$N$10)/($O$10-$N$10)))+$B$5*(IF($Q$10=$P$10,0,(H51-$P$10)/($Q$10-$P$10)))+$B$6*((K51-1)/4)+$B$7*(IF($S$10=$R$10,0,(L51-$R$10)/($S$10-$R$10)))) | N51: =IF(Z51="","",RANK(Z51,$Z$12:$Z$79,0)) | O51: =IF(N51="","",SUMIFS($M$12:$M$79,$N$12:$N$79,"<="&N51)/SUM($M$12:$M$79)) | P51: =IF(N51="","",IF(N51<=ROUNDUP(0.2*COUNT($M$12:$M$79),0),"A",IF(N51<=ROUNDUP(0.5*COUNT($M$12:$M$79),0),"B","C"))) | Q51: =IF(P51="","",IF(P51="A",0.5,IF(P51="B",0.3,IF(P51="C",0.15,"")))) | R51: =IF(B51="","",SUMIFS('Registro de Ingresos'!$C:$C,'Registro de Ingresos'!$B:$B,B51)-SUMIFS('Registro de Egresos'!$C:$C,'Registro de Egresos'!$B:$B,B51)) -> 0 | S51: =IF(OR(H51="",L51="",Q51="",F51="",F51=0),"",CEILING((H51/30*L51)*(1+Q51),F51)) | T51: =IF(OR(R51="",S51=""),"",IF(R51<=S51,"REPONER AHORA","OK")) | U51: =IF(OR(R51="",S51="",H51=""),"",IF(H51=0,"",$E$3+MAX(0,(R51-S51)/(H51/30)))) | V51: =IF(U51="","",DAY(U51)) | W51: =IF(V51="","",IF(V51>20,"FUERA DE VENTANA","DENTRO DE VENTANA")) | Z51: =IF(M51="","",M51+ROW()/100000000)
A52: 41 | B52: Banda lija tela gr 100 | C52: Consumible de ensayo | D52: Terminación | E52: 33302.15 | F52: 1 | G52: =IF(OR(E52="",F52=""),"",E52*F52) -> 33302.15 | H52: 1 | I52: 100 | J52: =IF(OR(G52="",I52=""),"",G52/I52) -> 333.0215 | K52: 1 | L52: 3 | M52: =IF(OR(E52="",H52="",K52="",L52=""),"",$B$4*(IF($O$10=$N$10,0,(E52-$N$10)/($O$10-$N$10)))+$B$5*(IF($Q$10=$P$10,0,(H52-$P$10)/($Q$10-$P$10)))+$B$6*((K52-1)/4)+$B$7*(IF($S$10=$R$10,0,(L52-$R$10)/($S$10-$R$10)))) -> 0.041121866 | N52: =IF(Z52="","",RANK(Z52,$Z$12:$Z$79,0)) -> 13 | O52: =IF(N52="","",SUMIFS($M$12:$M$79,$N$12:$N$79,"<="&N52)/SUM($M$12:$M$79)) -> 1 | P52: =IF(N52="","",IF(N52<=ROUNDUP(0.2*COUNT($M$12:$M$79),0),"A",IF(N52<=ROUNDUP(0.5*COUNT($M$12:$M$79),0),"B","C"))) -> C | Q52: =IF(P52="","",IF(P52="A",0.5,IF(P52="B",0.3,IF(P52="C",0.15,"")))) -> 0.15 | R52: =IF(B52="","",SUMIFS('Registro de Ingresos'!$C:$C,'Registro de Ingresos'!$B:$B,B52)-SUMIFS('Registro de Egresos'!$C:$C,'Registro de Egresos'!$B:$B,B52)) -> 0 | S52: =IF(OR(H52="",L52="",Q52="",F52="",F52=0),"",CEILING((H52/30*L52)*(1+Q52),F52)) -> 1 | T52: =IF(OR(R52="",S52=""),"",IF(R52<=S52,"REPONER AHORA","OK")) -> REPONER AHORA | U52: =IF(OR(R52="",S52="",H52=""),"",IF(H52=0,"",$E$3+MAX(0,(R52-S52)/(H52/30)))) -> 46265 | V52: =IF(U52="","",DAY(U52)) -> 31 | W52: =IF(V52="","",IF(V52>20,"FUERA DE VENTANA","DENTRO DE VENTANA")) -> FUERA DE VENTANA | Z52: =IF(M52="","",M52+ROW()/100000000) -> 0.041122386
A53: 42 | B53: Banda lija tela gr 80 | C53: Consumible de ensayo | D53: Terminación | E53: 33837.65 | F53: 1 | G53: =IF(OR(E53="",F53=""),"",E53*F53) -> 33837.65 | H53: 1 | I53: 100 | J53: =IF(OR(G53="",I53=""),"",G53/I53) -> 338.3765 | K53: 1 | L53: 3 | M53: =IF(OR(E53="",H53="",K53="",L53=""),"",$B$4*(IF($O$10=$N$10,0,(E53-$N$10)/($O$10-$N$10)))+$B$5*(IF($Q$10=$P$10,0,(H53-$P$10)/($Q$10-$P$10)))+$B$6*((K53-1)/4)+$B$7*(IF($S$10=$R$10,0,(L53-$R$10)/($S$10-$R$10)))) -> 0.041276006 | N53: =IF(Z53="","",RANK(Z53,$Z$12:$Z$79,0)) -> 12 | O53: =IF(N53="","",SUMIFS($M$12:$M$79,$N$12:$N$79,"<="&N53)/SUM($M$12:$M$79)) -> 0.99028733 | P53: =IF(N53="","",IF(N53<=ROUNDUP(0.2*COUNT($M$12:$M$79),0),"A",IF(N53<=ROUNDUP(0.5*COUNT($M$12:$M$79),0),"B","C"))) -> C | Q53: =IF(P53="","",IF(P53="A",0.5,IF(P53="B",0.3,IF(P53="C",0.15,"")))) -> 0.15 | R53: =IF(B53="","",SUMIFS('Registro de Ingresos'!$C:$C,'Registro de Ingresos'!$B:$B,B53)-SUMIFS('Registro de Egresos'!$C:$C,'Registro de Egresos'!$B:$B,B53)) -> 0 | S53: =IF(OR(H53="",L53="",Q53="",F53="",F53=0),"",CEILING((H53/30*L53)*(1+Q53),F53)) -> 1 | T53: =IF(OR(R53="",S53=""),"",IF(R53<=S53,"REPONER AHORA","OK")) -> REPONER AHORA | U53: =IF(OR(R53="",S53="",H53=""),"",IF(H53=0,"",$E$3+MAX(0,(R53-S53)/(H53/30)))) -> 46265 | V53: =IF(U53="","",DAY(U53)) -> 31 | W53: =IF(V53="","",IF(V53>20,"FUERA DE VENTANA","DENTRO DE VENTANA")) -> FUERA DE VENTANA | Z53: =IF(M53="","",M53+ROW()/100000000) -> 0.041276536
A54: 43 | B54: Inserto RCMX 2006 Mitsubishi | C54: Rendimiento múltiple (herramienta) | D54: Torneado | E54: 26640.53 | F54: 1 | G54: =IF(OR(E54="",F54=""),"",E54*F54) -> 26640.53 | H54: 1 | I54: 20 | J54: =IF(OR(G54="",I54=""),"",G54/I54) -> 1332.0265 | K54: 2 | L54: 5 | M54: =IF(OR(E54="",H54="",K54="",L54=""),"",$B$4*(IF($O$10=$N$10,0,(E54-$N$10)/($O$10-$N$10)))+$B$5*(IF($Q$10=$P$10,0,(H54-$P$10)/($Q$10-$P$10)))+$B$6*((K54-1)/4)+$B$7*(IF($S$10=$R$10,0,(L54-$R$10)/($S$10-$R$10)))) -> 0.19856825 | N54: =IF(Z54="","",RANK(Z54,$Z$12:$Z$79,0)) -> 10 | O54: =IF(N54="","",SUMIFS($M$12:$M$79,$N$12:$N$79,"<="&N54)/SUM($M$12:$M$79)) -> 0.93481674 | P54: =IF(N54="","",IF(N54<=ROUNDUP(0.2*COUNT($M$12:$M$79),0),"A",IF(N54<=ROUNDUP(0.5*COUNT($M$12:$M$79),0),"B","C"))) -> C | Q54: =IF(P54="","",IF(P54="A",0.5,IF(P54="B",0.3,IF(P54="C",0.15,"")))) -> 0.15 | R54: =IF(B54="","",SUMIFS('Registro de Ingresos'!$C:$C,'Registro de Ingresos'!$B:$B,B54)-SUMIFS('Registro de Egresos'!$C:$C,'Registro de Egresos'!$B:$B,B54)) -> 0 | S54: =IF(OR(H54="",L54="",Q54="",F54="",F54=0),"",CEILING((H54/30*L54)*(1+Q54),F54)) -> 1 | T54: =IF(OR(R54="",S54=""),"",IF(R54<=S54,"REPONER AHORA","OK")) -> REPONER AHORA | U54: =IF(OR(R54="",S54="",H54=""),"",IF(H54=0,"",$E$3+MAX(0,(R54-S54)/(H54/30)))) -> 46265 | V54: =IF(U54="","",DAY(U54)) -> 31 | W54: =IF(V54="","",IF(V54>20,"FUERA DE VENTANA","DENTRO DE VENTANA")) -> FUERA DE VENTANA | Z54: =IF(M54="","",M54+ROW()/100000000) -> 0.19856879
A55: 44 | B55: Porta H ext WTJNR 2020K16 | C55: Rendimiento múltiple (herramienta) | D55: Torneado | E55: 47600 | F55: 1 | G55: =IF(OR(E55="",F55=""),"",E55*F55) -> 47600 | H55: 0.17 | J55: =IF(OR(G55="",I55=""),"",G55/I55) | M55: =IF(OR(E55="",H55="",K55="",L55=""),"",$B$4*(IF($O$10=$N$10,0,(E55-$N$10)/($O$10-$N$10)))+$B$5*(IF($Q$10=$P$10,0,(H55-$P$10)/($Q$10-$P$10)))+$B$6*((K55-1)/4)+$B$7*(IF($S$10=$R$10,0,(L55-$R$10)/($S$10-$R$10)))) | N55: =IF(Z55="","",RANK(Z55,$Z$12:$Z$79,0)) | O55: =IF(N55="","",SUMIFS($M$12:$M$79,$N$12:$N$79,"<="&N55)/SUM($M$12:$M$79)) | P55: =IF(N55="","",IF(N55<=ROUNDUP(0.2*COUNT($M$12:$M$79),0),"A",IF(N55<=ROUNDUP(0.5*COUNT($M$12:$M$79),0),"B","C"))) | Q55: =IF(P55="","",IF(P55="A",0.5,IF(P55="B",0.3,IF(P55="C",0.15,"")))) | R55: =IF(B55="","",SUMIFS('Registro de Ingresos'!$C:$C,'Registro de Ingresos'!$B:$B,B55)-SUMIFS('Registro de Egresos'!$C:$C,'Registro de Egresos'!$B:$B,B55)) -> 0 | S55: =IF(OR(H55="",L55="",Q55="",F55="",F55=0),"",CEILING((H55/30*L55)*(1+Q55),F55)) | T55: =IF(OR(R55="",S55=""),"",IF(R55<=S55,"REPONER AHORA","OK")) | U55: =IF(OR(R55="",S55="",H55=""),"",IF(H55=0,"",$E$3+MAX(0,(R55-S55)/(H55/30)))) | V55: =IF(U55="","",DAY(U55)) | W55: =IF(V55="","",IF(V55>20,"FUERA DE VENTANA","DENTRO DE VENTANA")) | Z55: =IF(M55="","",M55+ROW()/100000000)
A56: 45 | B56: Repuesto placa base M1603 | C56: Consumible de ensayo | D56: Torneado | E56: 6842.5 | F56: 1 | G56: =IF(OR(E56="",F56=""),"",E56*F56) -> 6842.5 | H56: 0.83 | J56: =IF(OR(G56="",I56=""),"",G56/I56) | M56: =IF(OR(E56="",H56="",K56="",L56=""),"",$B$4*(IF($O$10=$N$10,0,(E56-$N$10)/($O$10-$N$10)))+$B$5*(IF($Q$10=$P$10,0,(H56-$P$10)/($Q$10-$P$10)))+$B$6*((K56-1)/4)+$B$7*(IF($S$10=$R$10,0,(L56-$R$10)/($S$10-$R$10)))) | N56: =IF(Z56="","",RANK(Z56,$Z$12:$Z$79,0)) | O56: =IF(N56="","",SUMIFS($M$12:$M$79,$N$12:$N$79,"<="&N56)/SUM($M$12:$M$79)) | P56: =IF(N56="","",IF(N56<=ROUNDUP(0.2*COUNT($M$12:$M$79),0),"A",IF(N56<=ROUNDUP(0.5*COUNT($M$12:$M$79),0),"B","C"))) | Q56: =IF(P56="","",IF(P56="A",0.5,IF(P56="B",0.3,IF(P56="C",0.15,"")))) | R56: =IF(B56="","",SUMIFS('Registro de Ingresos'!$C:$C,'Registro de Ingresos'!$B:$B,B56)-SUMIFS('Registro de Egresos'!$C:$C,'Registro de Egresos'!$B:$B,B56)) -> 0 | S56: =IF(OR(H56="",L56="",Q56="",F56="",F56=0),"",CEILING((H56/30*L56)*(1+Q56),F56)) | T56: =IF(OR(R56="",S56=""),"",IF(R56<=S56,"REPONER AHORA","OK")) | U56: =IF(OR(R56="",S56="",H56=""),"",IF(H56=0,"",$E$3+MAX(0,(R56-S56)/(H56/30)))) | V56: =IF(U56="","",DAY(U56)) | W56: =IF(V56="","",IF(V56>20,"FUERA DE VENTANA","DENTRO DE VENTANA")) | Z56: =IF(M56="","",M56+ROW()/100000000)
A57: 46 | B57: Inserto APKT 160408 PH792 | C57: Rendimiento múltiple (herramienta) | D57: Fresado | E57: 9722.3 | F57: 6 | G57: =IF(OR(E57="",F57=""),"",E57*F57) -> 58333.8 | H57: 2 | I57: 30 | J57: =IF(OR(G57="",I57=""),"",G57/I57) -> 1944.46 | K57: 2 | L57: 5 | M57: =IF(OR(E57="",H57="",K57="",L57=""),"",$B$4*(IF($O$10=$N$10,0,(E57-$N$10)/($O$10-$N$10)))+$B$5*(IF($Q$10=$P$10,0,(H57-$P$10)/($Q$10-$P$10)))+$B$6*((K57-1)/4)+$B$7*(IF($S$10=$R$10,0,(L57-$R$10)/($S$10-$R$10)))) -> 0.20940628 | N57: =IF(Z57="","",RANK(Z57,$Z$12:$Z$79,0)) -> 7 | O57: =IF(N57="","",SUMIFS($M$12:$M$79,$N$12:$N$79,"<="&N57)/SUM($M$12:$M$79)) -> 0.78917003 | P57: =IF(N57="","",IF(N57<=ROUNDUP(0.2*COUNT($M$12:$M$79),0),"A",IF(N57<=ROUNDUP(0.5*COUNT($M$12:$M$79),0),"B","C"))) -> B | Q57: =IF(P57="","",IF(P57="A",0.5,IF(P57="B",0.3,IF(P57="C",0.15,"")))) -> 0.3 | R57: =IF(B57="","",SUMIFS('Registro de Ingresos'!$C:$C,'Registro de Ingresos'!$B:$B,B57)-SUMIFS('Registro de Egresos'!$C:$C,'Registro de Egresos'!$B:$B,B57)) -> 0 | S57: =IF(OR(H57="",L57="",Q57="",F57="",F57=0),"",CEILING((H57/30*L57)*(1+Q57),F57)) -> 6 | T57: =IF(OR(R57="",S57=""),"",IF(R57<=S57,"REPONER AHORA","OK")) -> REPONER AHORA | U57: =IF(OR(R57="",S57="",H57=""),"",IF(H57=0,"",$E$3+MAX(0,(R57-S57)/(H57/30)))) -> 46265 | V57: =IF(U57="","",DAY(U57)) -> 31 | W57: =IF(V57="","",IF(V57>20,"FUERA DE VENTANA","DENTRO DE VENTANA")) -> FUERA DE VENTANA | Z57: =IF(M57="","",M57+ROW()/100000000) -> 0.20940685
...

Sheet Vista General
A1: Vista general de insumos — Control de Insumos Críticos SIMET-USACH
A2: Resumen consolidado: clasificación, ubicación, stock y alertas de todos los insumos catastrados.
A4: ID | B4: Insumo | C4: Categoría | D4: Ubicación | E4: Clase ABC | F4: Stock actual | G4: Stock mínimo | H4: Alerta nivel de stock | I4: Alerta ventana de compra
A5: =IF('Catálogo de Insumos'!$B12="","",IF('Catálogo de Insumos'!A12="","",'Catálogo de Insumos'!A12)) -> 1 | B5: =IF('Catálogo de Insumos'!$B12="","",IF('Catálogo de Insumos'!B12="","",'Catálogo de Insumos'!B12)) -> Cut Off Wheels, A303020, 300×32×2.0mm | C5: =IF('Catálogo de Insumos'!$B12="","",IF('Catálogo de Insumos'!C12="","",'Catálogo de Insumos'!C12)) -> Consumible de metalografía | D5: =IF('Catálogo de Insumos'!$B12="","",IF('Catálogo de Insumos'!Y12="","",'Catálogo de Insumos'!Y12)) | E5: =IF('Catálogo de Insumos'!$B12="","",IF('Catálogo de Insumos'!P12="","",'Catálogo de Insumos'!P12)) | F5: =IF('Catálogo de Insumos'!$B12="","",IF('Catálogo de Insumos'!R12="","",'Catálogo de Insumos'!R12)) -> 0 | G5: =IF('Catálogo de Insumos'!$B12="","",IF('Catálogo de Insumos'!S12="","",'Catálogo de Insumos'!S12)) | H5: =IF('Catálogo de Insumos'!$B12="","",IF('Catálogo de Insumos'!T12="","",'Catálogo de Insumos'!T12)) | I5: =IF('Catálogo de Insumos'!$B12="","",IF('Catálogo de Insumos'!W12="","",'Catálogo de Insumos'!W12))
A6: =IF('Catálogo de Insumos'!$B13="","",IF('Catálogo de Insumos'!A13="","",'Catálogo de Insumos'!A13)) -> 2 | B6: =IF('Catálogo de Insumos'!$B13="","",IF('Catálogo de Insumos'!B13="","",'Catálogo de Insumos'!B13)) -> Cut Off Wheels, A503020, 300×32×2.0mm | C6: =IF('Catálogo de Insumos'!$B13="","",IF('Catálogo de Insumos'!C13="","",'Catálogo de Insumos'!C13)) -> Consumible de metalografía | D6: =IF('Catálogo de Insumos'!$B13="","",IF('Catálogo de Insumos'!Y13="","",'Catálogo de Insumos'!Y13)) | E6: =IF('Catálogo de Insumos'!$B13="","",IF('Catálogo de Insumos'!P13="","",'Catálogo de Insumos'!P13)) | F6: =IF('Catálogo de Insumos'!$B13="","",IF('Catálogo de Insumos'!R13="","",'Catálogo de Insumos'!R13)) -> 0 | G6: =IF('Catálogo de Insumos'!$B13="","",IF('Catálogo de Insumos'!S13="","",'Catálogo de Insumos'!S13)) | H6: =IF('Catálogo de Insumos'!$B13="","",IF('Catálogo de Insumos'!T13="","",'Catálogo de Insumos'!T13)) | I6: =IF('Catálogo de Insumos'!$B13="","",IF('Catálogo de Insumos'!W13="","",'Catálogo de Insumos'!W13))
A7: =IF('Catálogo de Insumos'!$B14="","",IF('Catálogo de Insumos'!A14="","",'Catálogo de Insumos'!A14)) -> 3 | B7: =IF('Catálogo de Insumos'!$B14="","",IF('Catálogo de Insumos'!B14="","",'Catálogo de Insumos'!B14)) -> Cut Off Wheels, A603020, 300×32×2.0mm | C7: =IF('Catálogo de Insumos'!$B14="","",IF('Catálogo de Insumos'!C14="","",'Catálogo de Insumos'!C14)) -> Consumible de metalografía | D7: =IF('Catálogo de Insumos'!$B14="","",IF('Catálogo de Insumos'!Y14="","",'Catálogo de Insumos'!Y14)) | E7: =IF('Catálogo de Insumos'!$B14="","",IF('Catálogo de Insumos'!P14="","",'Catálogo de Insumos'!P14)) | F7: =IF('Catálogo de Insumos'!$B14="","",IF('Catálogo de Insumos'!R14="","",'Catálogo de Insumos'!R14)) -> 0 | G7: =IF('Catálogo de Insumos'!$B14="","",IF('Catálogo de Insumos'!S14="","",'Catálogo de Insumos'!S14)) | H7: =IF('Catálogo de Insumos'!$B14="","",IF('Catálogo de Insumos'!T14="","",'Catálogo de Insumos'!T14)) | I7: =IF('Catálogo de Insumos'!$B14="","",IF('Catálogo de Insumos'!W14="","",'Catálogo de Insumos'!W14))
A8: =IF('Catálogo de Insumos'!$B15="","",IF('Catálogo de Insumos'!A15="","",'Catálogo de Insumos'!A15)) -> 4 | B8: =IF('Catálogo de Insumos'!$B15="","",IF('Catálogo de Insumos'!B15="","",'Catálogo de Insumos'!B15)) -> Plastic Clip, Red, X-sample | C8: =IF('Catálogo de Insumos'!$B15="","",IF('Catálogo de Insumos'!C15="","",'Catálogo de Insumos'!C15)) -> Consumible de metalografía | D8: =IF('Catálogo de Insumos'!$B15="","",IF('Catálogo de Insumos'!Y15="","",'Catálogo de Insumos'!Y15)) | E8: =IF('Catálogo de Insumos'!$B15="","",IF('Catálogo de Insumos'!P15="","",'Catálogo de Insumos'!P15)) | F8: =IF('Catálogo de Insumos'!$B15="","",IF('Catálogo de Insumos'!R15="","",'Catálogo de Insumos'!R15)) -> 0 | G8: =IF('Catálogo de Insumos'!$B15="","",IF('Catálogo de Insumos'!S15="","",'Catálogo de Insumos'!S15)) | H8: =IF('Catálogo de Insumos'!$B15="","",IF('Catálogo de Insumos'!T15="","",'Catálogo de Insumos'!T15)) | I8: =IF('Catálogo de Insumos'!$B15="","",IF('Catálogo de Insumos'!W15="","",'Catálogo de Insumos'!W15))
A9: =IF('Catálogo de Insumos'!$B16="","",IF('Catálogo de Insumos'!A16="","",'Catálogo de Insumos'!A16)) -> 5 | B9: =IF('Catálogo de Insumos'!$B16="","",IF('Catálogo de Insumos'!B16="","",'Catálogo de Insumos'!B16)) -> Plastic Clip, Green, X-sample | C9: =IF('Catálogo de Insumos'!$B16="","",IF('Catálogo de Insumos'!C16="","",'Catálogo de Insumos'!C16)) -> Consumible de metalografía | D9: =IF('Catálogo de Insumos'!$B16="","",IF('Catálogo de Insumos'!Y16="","",'Catálogo de Insumos'!Y16)) | E9: =IF('Catálogo de Insumos'!$B16="","",IF('Catálogo de Insumos'!P16="","",'Catálogo de Insumos'!P16)) | F9: =IF('Catálogo de Insumos'!$B16="","",IF('Catálogo de Insumos'!R16="","",'Catálogo de Insumos'!R16)) -> 0 | G9: =IF('Catálogo de Insumos'!$B16="","",IF('Catálogo de Insumos'!S16="","",'Catálogo de Insumos'!S16)) | H9: =IF('Catálogo de Insumos'!$B16="","",IF('Catálogo de Insumos'!T16="","",'Catálogo de Insumos'!T16)) | I9: =IF('Catálogo de Insumos'!$B16="","",IF('Catálogo de Insumos'!W16="","",'Catálogo de Insumos'!W16))
A10: =IF('Catálogo de Insumos'!$B17="","",IF('Catálogo de Insumos'!A17="","",'Catálogo de Insumos'!A17)) -> 6 | B10: =IF('Catálogo de Insumos'!$B17="","",IF('Catálogo de Insumos'!B17="","",'Catálogo de Insumos'!B17)) -> Plastic Clip, White, X-sample | C10: =IF('Catálogo de Insumos'!$B17="","",IF('Catálogo de Insumos'!C17="","",'Catálogo de Insumos'!C17)) -> Consumible de metalografía | D10: =IF('Catálogo de Insumos'!$B17="","",IF('Catálogo de Insumos'!Y17="","",'Catálogo de Insumos'!Y17)) | E10: =IF('Catálogo de Insumos'!$B17="","",IF('Catálogo de Insumos'!P17="","",'Catálogo de Insumos'!P17)) | F10: =IF('Catálogo de Insumos'!$B17="","",IF('Catálogo de Insumos'!R17="","",'Catálogo de Insumos'!R17)) -> 0 | G10: =IF('Catálogo de Insumos'!$B17="","",IF('Catálogo de Insumos'!S17="","",'Catálogo de Insumos'!S17)) | H10: =IF('Catálogo de Insumos'!$B17="","",IF('Catálogo de Insumos'!T17="","",'Catálogo de Insumos'!T17)) | I10: =IF('Catálogo de Insumos'!$B17="","",IF('Catálogo de Insumos'!W17="","",'Catálogo de Insumos'!W17))
A11: =IF('Catálogo de Insumos'!$B18="","",IF('Catálogo de Insumos'!A18="","",'Catálogo de Insumos'!A18)) -> 7 | B11: =IF('Catálogo de Insumos'!$B18="","",IF('Catálogo de Insumos'!B18="","",'Catálogo de Insumos'!B18)) -> Sample Holder | C11: =IF('Catálogo de Insumos'!$B18="","",IF('Catálogo de Insumos'!C18="","",'Catálogo de Insumos'!C18)) -> Consumible de metalografía | D11: =IF('Catálogo de Insumos'!$B18="","",IF('Catálogo de Insumos'!Y18="","",'Catálogo de Insumos'!Y18)) | E11: =IF('Catálogo de Insumos'!$B18="","",IF('Catálogo de Insumos'!P18="","",'Catálogo de Insumos'!P18)) | F11: =IF('Catálogo de Insumos'!$B18="","",IF('Catálogo de Insumos'!R18="","",'Catálogo de Insumos'!R18)) -> 0 | G11: =IF('Catálogo de Insumos'!$B18="","",IF('Catálogo de Insumos'!S18="","",'Catálogo de Insumos'!S18)) | H11: =IF('Catálogo de Insumos'!$B18="","",IF('Catálogo de Insumos'!T18="","",'Catálogo de Insumos'!T18)) | I11: =IF('Catálogo de Insumos'!$B18="","",IF('Catálogo de Insumos'!W18="","",'Catálogo de Insumos'!W18))
A12: =IF('Catálogo de Insumos'!$B19="","",IF('Catálogo de Insumos'!A19="","",'Catálogo de Insumos'!A19)) -> 8 | B12: =IF('Catálogo de Insumos'!$B19="","",IF('Catálogo de Insumos'!B19="","",'Catálogo de Insumos'!B19)) -> Abrasive Paper, Silicon Carbide, PSA, 250mm, 180# | C12: =IF('Catálogo de Insumos'!$B19="","",IF('Catálogo de Insumos'!C19="","",'Catálogo de Insumos'!C19)) -> Consumible de metalografía | D12: =IF('Catálogo de Insumos'!$B19="","",IF('Catálogo de Insumos'!Y19="","",'Catálogo de Insumos'!Y19)) | E12: =IF('Catálogo de Insumos'!$B19="","",IF('Catálogo de Insumos'!P19="","",'Catálogo de Insumos'!P19)) | F12: =IF('Catálogo de Insumos'!$B19="","",IF('Catálogo de Insumos'!R19="","",'Catálogo de Insumos'!R19)) -> 0 | G12: =IF('Catálogo de Insumos'!$B19="","",IF('Catálogo de Insumos'!S19="","",'Catálogo de Insumos'!S19)) | H12: =IF('Catálogo de Insumos'!$B19="","",IF('Catálogo de Insumos'!T19="","",'Catálogo de Insumos'!T19)) | I12: =IF('Catálogo de Insumos'!$B19="","",IF('Catálogo de Insumos'!W19="","",'Catálogo de Insumos'!W19))
A13: =IF('Catálogo de Insumos'!$B20="","",IF('Catálogo de Insumos'!A20="","",'Catálogo de Insumos'!A20)) -> 9 | B13: =IF('Catálogo de Insumos'!$B20="","",IF('Catálogo de Insumos'!B20="","",'Catálogo de Insumos'!B20)) -> Abrasive Paper, Silicon Carbide, PSA, 250mm, 400# | C13: =IF('Catálogo de Insumos'!$B20="","",IF('Catálogo de Insumos'!C20="","",'Catálogo de Insumos'!C20)) -> Consumible de metalografía | D13: =IF('Catálogo de Insumos'!$B20="","",IF('Catálogo de Insumos'!Y20="","",'Catálogo de Insumos'!Y20)) | E13: =IF('Catálogo de Insumos'!$B20="","",IF('Catálogo de Insumos'!P20="","",'Catálogo de Insumos'!P20)) | F13: =IF('Catálogo de Insumos'!$B20="","",IF('Catálogo de Insumos'!R20="","",'Catálogo de Insumos'!R20)) -> 0 | G13: =IF('Catálogo de Insumos'!$B20="","",IF('Catálogo de Insumos'!S20="","",'Catálogo de Insumos'!S20)) | H13: =IF('Catálogo de Insumos'!$B20="","",IF('Catálogo de Insumos'!T20="","",'Catálogo de Insumos'!T20)) | I13: =IF('Catálogo de Insumos'!$B20="","",IF('Catálogo de Insumos'!W20="","",'Catálogo de Insumos'!W20))
A14: =IF('Catálogo de Insumos'!$B21="","",IF('Catálogo de Insumos'!A21="","",'Catálogo de Insumos'!A21)) -> 10 | B14: =IF('Catálogo de Insumos'!$B21="","",IF('Catálogo de Insumos'!B21="","",'Catálogo de Insumos'!B21)) -> Abrasive Paper, Silicon Carbide, PSA, 250mm, 800# | C14: =IF('Catálogo de Insumos'!$B21="","",IF('Catálogo de Insumos'!C21="","",'Catálogo de Insumos'!C21)) -> Consumible de metalografía | D14: =IF('Catálogo de Insumos'!$B21="","",IF('Catálogo de Insumos'!Y21="","",'Catálogo de Insumos'!Y21)) | E14: =IF('Catálogo de Insumos'!$B21="","",IF('Catálogo de Insumos'!P21="","",'Catálogo de Insumos'!P21)) | F14: =IF('Catálogo de Insumos'!$B21="","",IF('Catálogo de Insumos'!R21="","",'Catálogo de Insumos'!R21)) -> 0 | G14: =IF('Catálogo de Insumos'!$B21="","",IF('Catálogo de Insumos'!S21="","",'Catálogo de Insumos'!S21)) | H14: =IF('Catálogo de Insumos'!$B21="","",IF('Catálogo de Insumos'!T21="","",'Catálogo de Insumos'!T21)) | I14: =IF('Catálogo de Insumos'!$B21="","",IF('Catálogo de Insumos'!W21="","",'Catálogo de Insumos'!W21))
A15: =IF('Catálogo de Insumos'!$B22="","",IF('Catálogo de Insumos'!A22="","",'Catálogo de Insumos'!A22)) -> 11 | B15: =IF('Catálogo de Insumos'!$B22="","",IF('Catálogo de Insumos'!B22="","",'Catálogo de Insumos'!B22)) -> Abrasive Paper, Silicon Carbide, PSA, 250mm, 1200# | C15: =IF('Catálogo de Insumos'!$B22="","",IF('Catálogo de Insumos'!C22="","",'Catálogo de Insumos'!C22)) -> Consumible de metalografía | D15: =IF('Catálogo de Insumos'!$B22="","",IF('Catálogo de Insumos'!Y22="","",'Catálogo de Insumos'!Y22)) | E15: =IF('Catálogo de Insumos'!$B22="","",IF('Catálogo de Insumos'!P22="","",'Catálogo de Insumos'!P22)) | F15: =IF('Catálogo de Insumos'!$B22="","",IF('Catálogo de Insumos'!R22="","",'Catálogo de Insumos'!R22)) -> 0 | G15: =IF('Catálogo de Insumos'!$B22="","",IF('Catálogo de Insumos'!S22="","",'Catálogo de Insumos'!S22)) | H15: =IF('Catálogo de Insumos'!$B22="","",IF('Catálogo de Insumos'!T22="","",'Catálogo de Insumos'!T22)) | I15: =IF('Catálogo de Insumos'!$B22="","",IF('Catálogo de Insumos'!W22="","",'Catálogo de Insumos'!W22))
A16: =IF('Catálogo de Insumos'!$B23="","",IF('Catálogo de Insumos'!A23="","",'Catálogo de Insumos'!A23)) -> 12 | B16: =IF('Catálogo de Insumos'!$B23="","",IF('Catálogo de Insumos'!B23="","",'Catálogo de Insumos'!B23)) -> Abrasive Paper, Silicon Carbide, PSA, 250mm, 2400# | C16: =IF('Catálogo de Insumos'!$B23="","",IF('Catálogo de Insumos'!C23="","",'Catálogo de Insumos'!C23)) -> Consumible de metalografía | D16: =IF('Catálogo de Insumos'!$B23="","",IF('Catálogo de Insumos'!Y23="","",'Catálogo de Insumos'!Y23)) | E16: =IF('Catálogo de Insumos'!$B23="","",IF('Catálogo de Insumos'!P23="","",'Catálogo de Insumos'!P23)) | F16: =IF('Catálogo de Insumos'!$B23="","",IF('Catálogo de Insumos'!R23="","",'Catálogo de Insumos'!R23)) -> 0 | G16: =IF('Catálogo de Insumos'!$B23="","",IF('Catálogo de Insumos'!S23="","",'Catálogo de Insumos'!S23)) | H16: =IF('Catálogo de Insumos'!$B23="","",IF('Catálogo de Insumos'!T23="","",'Catálogo de Insumos'!T23)) | I16: =IF('Catálogo de Insumos'!$B23="","",IF('Catálogo de Insumos'!W23="","",'Catálogo de Insumos'!W23))
... A72: =IF('Catálogo de Insumos'!$B79="","",IF('Catálogo de Insumos'!A79="","",'Catálogo de Insumos'!A79)) -> 68 | B72: =IF('Catálogo de Insumos'!$B79="","",IF('Catálogo de Insumos'!B79="","",'Catálogo de Insumos'!B79)) -> Alcohol metílico 5 L | C72: =IF('Catálogo de Insumos'!$B79="","",IF('Catálogo de Insumos'!C79="","",'Catálogo de Insumos'!C79)) -> Consumible de ensayo | D72: =IF('Catálogo de Insumos'!$B79="","",IF('Catálogo de Insumos'!Y79="","",'Catálogo de Insumos'!Y79)) | E72: =IF('Catálogo de Insumos'!$B79="","",IF('Catálogo de Insumos'!P79="","",'Catálogo de Insumos'!P79)) -> B | F72: =IF('Catálogo de Insumos'!$B79="","",IF('Catálogo de Insumos'!R79="","",'Catálogo de Insumos'!R79)) -> 0 | G72: =IF('Catálogo de Insumos'!$B79="","",IF('Catálogo de Insumos'!S79="","",'Catálogo de Insumos'!S79)) -> 1 | H72: =IF('Catálogo de Insumos'!$B79="","",IF('Catálogo de Insumos'!T79="","",'Catálogo de Insumos'!T79)) -> REPONER AHORA | I72: =IF('Catálogo de Insumos'!$B79="","",IF('Catálogo de Insumos'!W79="","",'Catálogo de Insumos'!W79)) -> FUERA DE VENTANA

Sheet Registro de Ingresos
A1: REGISTRO DE INGRESOS — Control de Insumos Críticos SIMET-USACH
A3: Fecha | B3: Insumo | C3: Cantidad | D3: Responsable | E3: Observación
A4: 46037 | B4: Ejemplo: Sierra bimetal 1" 4-6 E0,9 (no usar como dato real) | C4: 3 | D4: M. Contreras | E4: Fila de ejemplo — bórrela o ignórela al registrar datos reales

Sheet Registro de Egresos
A1: REGISTRO DE EGRESOS — Control de Insumos Críticos SIMET-USACH
A3: Fecha | B3: Insumo | C3: Cantidad | D3: Responsable / RAM asociado | E3: Observación
A4: 46037 | B4: Ejemplo: Sierra bimetal 1" 4-6 E0,9 (no usar como dato real) | C4: 3 | D4: J. Pérez — RAM 2026-0341 | E4: Fila de ejemplo — bórrela o ignórela al registrar datos reales
